jinja2.exceptions.UndefinedError
jinja2.exceptions.UndefinedError: 'dict object' has no attribute 'learning_confidence'

Traceback (most recent call last)
This is the Copy/Paste friendly version of the traceback.

Traceback (most recent call last):
  File "/Library/Frameworks/Python.framework/Versions/3.13/lib/python3.13/site-packages/flask/app.py", line 1536, in call
    return self.wsgi_app(environ, start_response)
           ~~~~~~~~~~~~~^^^^^^^^^^^^^^^^^^^^^^^^^
  File "/Library/Frameworks/Python.framework/Versions/3.13/lib/python3.13/site-packages/werkzeug/middleware/proxy_fix.py", line 183, in call
    return self.app(environ, start_response)
           ~~~~~~^^^^^^^^^^^^^^^^^^^^^^^^^
  File "/Library/Frameworks/Python.framework/Versions/3.13/lib/python3.13/site-packages/flask/app.py", line 1514, in wsgi_app
    response = self.handle_exception(e)
  File "/Library/Frameworks/Python.framework/Versions/3.13/lib/python3.13/site-packages/flask/app.py", line 1511, in wsgi_app
    response = self.full_dispatch_request()
  File "/Library/Frameworks/Python.framework/Versions/3.13/lib/python3.13/site-packages/flask/app.py", line 919, in full_dispatch_request
    rv = self.handle_user_exception(e)
  File "/Library/Frameworks/Python.framework/Versions/3.13/lib/python3.13/site-packages/flask/app.py", line 917, in full_dispatch_request
    rv = self.dispatch_request()
  File "/Library/Frameworks/Python.framework/Versions/3.13/lib/python3.13/site-packages/flask/app.py", line 902, in dispatch_request
    return self.ensure_sync(self.view_functions[rule.endpoint])(**view_args)  # type: ignore[no-any-return]
           ~~~~~~~~~~~~~~~~~~~~~~~~~~~~~~~~~~~~~~~~~~~~~~~~^^^^^^^^^^^^^
  File "/Users/rudolph.vanstaden/Downloads/EG/routes.py", line 738, in adaptive_ml_dashboard
    return render_template('adaptive_ml_dashboard.html',
           ^^^^^^^^^^^^^^^^^^^^^^^^^^^^^^^^^^
  File "/Library/Frameworks/Python.framework/Versions/3.13/lib/python3.13/site-packages/flask/templating.py", line 150, in render_template
    return _render(app, template, context)
  File "/Library/Frameworks/Python.framework/Versions/3.13/lib/python3.13/site-packages/flask/templating.py", line 131, in _render
    rv = template.render(context)
  File "/Library/Frameworks/Python.framework/Versions/3.13/lib/python3.13/site-packages/jinja2/environment.py", line 1295, in render
    self.environment.handle_exception()
    ~~~~~~~~~~~~~~~~~~~~~~~~~~~~~~~^^
  File "/Library/Frameworks/Python.framework/Versions/3.13/lib/python3.13/site-packages/jinja2/environment.py", line 942, in handle_exception
    raise rewrite_traceback_stack(source=source)
  File "/Users/rudolph.vanstaden/Downloads/EG/templates/adaptive_ml_dashboard.html", line 1, in top-level template code
    {% extends "base.html" %}
  File "/Users/rudolph.vanstaden/Downloads/EG/templates/base.html", line 281, in top-level template code
    {% block content %}{% endblock %}
    ^^^^^^^^^^^^^^^^^
  File "/Users/rudolph.vanstaden/Downloads/EG/templates/adaptive_ml_dashboard.html", line 96, in block 'content'
    style="width: {{ ((analytics.performance_metrics.learning_confidence if analytics and analytics.performance_metrics else 0) * 100) }}%">
    
jinja2.exceptions.UndefinedError: 'dict object' has no attribute 'learning_confidence'