sqlalchemy.exc.OperationalError
sqlalchemy.exc.OperationalError: (sqlite3.OperationalError) no such column: processing_sessions.current_chunk
[SQL: SELECT processing_sessions.id AS processing_sessions_id, processing_sessions.filename AS processing_sessions_filename, processing_sessions.upload_time AS processing_sessions_upload_time, processing_sessions.total_records AS processing_sessions_total_records, processing_sessions.processed_records AS processing_sessions_processed_records, processing_sessions.status AS processing_sessions_status, processing_sessions.error_message AS processing_sessions_error_message, processing_sessions.processing_stats AS processing_sessions_processing_stats, processing_sessions.data_path AS processing_sessions_data_path, processing_sessions.is_compressed AS processing_sessions_is_compressed, processing_sessions.exclusion_applied AS processing_sessions_exclusion_applied, processing_sessions.whitelist_applied AS processing_sessions_whitelist_applied, processing_sessions.rules_applied AS processing_sessions_rules_applied, processing_sessions.ml_applied AS processing_sessions_ml_applied, processing_sessions.current_chunk AS processing_sessions_current_chunk, processing_sessions.total_chunks AS processing_sessions_total_chunks 
FROM processing_sessions ORDER BY processing_sessions.upload_time DESC
 LIMIT ? OFFSET ?]
[parameters: (10, 0)]
(Background on this error at: https://sqlalche.me/e/20/e3q8)

Traceback (most recent call last)
This is the Copy/Paste friendly version of the traceback.

Traceback (most recent call last):
  File "C:\Users\Christiaan\AppData\Roaming\Python\Python313\site-packages\sqlalchemy\engine\base.py", line 1963, in _exec_single_context
    self.dialect.do_execute(
    ^
  File "C:\Users\Christiaan\AppData\Roaming\Python\Python313\site-packages\sqlalchemy\engine\default.py", line 943, in do_execute
    cursor.execute(statement, parameters)
    ~~~~~~~~~~~~~~^^^^^^^^^^^^^^^^^^^^^^^
sqlite3.OperationalError: no such column: processing_sessions.current_chunk

The above exception was the direct cause of the following exception:

Traceback (most recent call last):
  File "C:\Users\Christiaan\AppData\Roaming\Python\Python313\site-packages\flask\app.py", line 1536, in __call__
    return self.wsgi_app(environ, start_response)
           ~~~~~~~~~~~~~^^^^^^^^^^^^^^^^^^^^^^^^^
  File "C:\Users\Christiaan\AppData\Roaming\Python\Python313\site-packages\werkzeug\middleware\proxy_fix.py", line 183, in __call__
    return self.app(environ, start_response)
           ~~~~~~~~^^^^^^^^^^^^^^^^^^^^^^^^^
  File "C:\Users\Christiaan\AppData\Roaming\Python\Python313\site-packages\flask\app.py", line 1514, in wsgi_app
    response = self.handle_exception(e)
  File "C:\Users\Christiaan\AppData\Roaming\Python\Python313\site-packages\flask\app.py", line 1511, in wsgi_app
    response = self.full_dispatch_request()
  File "C:\Users\Christiaan\AppData\Roaming\Python\Python313\site-packages\flask\app.py", line 919, in full_dispatch_request
    rv = self.handle_user_exception(e)
  File "C:\Users\Christiaan\AppData\Roaming\Python\Python313\site-packages\flask\app.py", line 917, in full_dispatch_request
    rv = self.dispatch_request()
  File "C:\Users\Christiaan\AppData\Roaming\Python\Python313\site-packages\flask\app.py", line 902, in dispatch_request
    return self.ensure_sync(self.view_functions[rule.endpoint])(**view_args)  # type: ignore[no-any-return]
           ~~~~~~~~~~~~~~~~~~~~~~~~~~~~~~~~~~~~~~~~~~~~~~~~~~~~^^^^^^^^^^^^^
  File "D:\EM_1\routes.py", line 30, in index
    recent_sessions = ProcessingSession.query.order_by(ProcessingSession.upload_time.desc()).limit(10).all()
  File "C:\Users\Christiaan\AppData\Roaming\Python\Python313\site-packages\sqlalchemy\orm\query.py", line 2704, in all
    return self._iter().all()  # type: ignore
           ~~~~~~~~~~^^
  File "C:\Users\Christiaan\AppData\Roaming\Python\Python313\site-packages\sqlalchemy\orm\query.py", line 2857, in _iter
    result: Union[ScalarResult[_T], Result[_T]] = self.session.execute(
    
  File "C:\Users\Christiaan\AppData\Roaming\Python\Python313\site-packages\sqlalchemy\orm\session.py", line 2365, in execute
    return self._execute_internal(
    
  File "C:\Users\Christiaan\AppData\Roaming\Python\Python313\site-packages\sqlalchemy\orm\session.py", line 2251, in _execute_internal
    result: Result[Any] = compile_state_cls.orm_execute_statement(
    
  File "C:\Users\Christiaan\AppData\Roaming\Python\Python313\site-packages\sqlalchemy\orm\context.py", line 306, in orm_execute_statement
    result = conn.execute(
    
  File "C:\Users\Christiaan\AppData\Roaming\Python\Python313\site-packages\sqlalchemy\engine\base.py", line 1415, in execute
    return meth(
    
  File "C:\Users\Christiaan\AppData\Roaming\Python\Python313\site-packages\sqlalchemy\sql\elements.py", line 523, in _execute_on_connection
    return connection._execute_clauseelement(
    
  File "C:\Users\Christiaan\AppData\Roaming\Python\Python313\site-packages\sqlalchemy\engine\base.py", line 1637, in _execute_clauseelement
    ret = self._execute_context(
    
  File "C:\Users\Christiaan\AppData\Roaming\Python\Python313\site-packages\sqlalchemy\engine\base.py", line 1842, in _execute_context
    return self._exec_single_context(
    
  File "C:\Users\Christiaan\AppData\Roaming\Python\Python313\site-packages\sqlalchemy\engine\base.py", line 1982, in _exec_single_context
    self._handle_dbapi_exception(
    ^
  File "C:\Users\Christiaan\AppData\Roaming\Python\Python313\site-packages\sqlalchemy\engine\base.py", line 2351, in _handle_dbapi_exception
    raise sqlalchemy_exception.with_traceback(exc_info[2]) from e
  File "C:\Users\Christiaan\AppData\Roaming\Python\Python313\site-packages\sqlalchemy\engine\base.py", line 1963, in _exec_single_context
    self.dialect.do_execute(
    ^
  File "C:\Users\Christiaan\AppData\Roaming\Python\Python313\site-packages\sqlalchemy\engine\default.py", line 943, in do_execute
    cursor.execute(statement, parameters)
    ~~~~~~~~~~~~~~^^^^^^^^^^^^^^^^^^^^^^^
sqlalchemy.exc.OperationalError: (sqlite3.OperationalError) no such column: processing_sessions.current_chunk
[SQL: SELECT processing_sessions.id AS processing_sessions_id, processing_sessions.filename AS processing_sessions_filename, processing_sessions.upload_time AS processing_sessions_upload_time, processing_sessions.total_records AS processing_sessions_total_records, processing_sessions.processed_records AS processing_sessions_processed_records, processing_sessions.status AS processing_sessions_status, processing_sessions.error_message AS processing_sessions_error_message, processing_sessions.processing_stats AS processing_sessions_processing_stats, processing_sessions.data_path AS processing_sessions_data_path, processing_sessions.is_compressed AS processing_sessions_is_compressed, processing_sessions.exclusion_applied AS processing_sessions_exclusion_applied, processing_sessions.whitelist_applied AS processing_sessions_whitelist_applied, processing_sessions.rules_applied AS processing_sessions_rules_applied, processing_sessions.ml_applied AS processing_sessions_ml_applied, processing_sessions.current_chunk AS processing_sessions_current_chunk, processing_sessions.total_chunks AS processing_sessions_total_chunks 
FROM processing_sessions ORDER BY processing_sessions.upload_time DESC
 LIMIT ? OFFSET ?]
[parameters: (10, 0)]
(Background on this error at: https://sqlalche.me/e/20/e3q8)